Workbook

Sheet redshift_table
B1: All | E1: Set_A_m1_231023 | H1: Set_C | K1: Set_B_p1
A2: slit | B2: z | C2: conf | D2: spec_quality | E2: grade1 | F2: z1 | G2: lines1 | H2: grade3 | I2: z3 | J2: lines3 | K2: grade2 | L2: z2 | M2: lines2 | N2: note | O2: bad_line | P2: slit_RA | Q2: slit_DEC | R2: M_s | S2: M_s_err | T2: g1_bestfit | U2: g1_peak | V2: g1_median | W2: g1_err- | X2: g1_err+ | Y2: g2_bestfit | Z2: g2_peak | AA2: g2_median | AB2: g2_err- | AC2: g2_err+ | AD2: theta_int_bestfit | AE2: theta_int_peak | AF2: theta_int_median | AG2: theta_int_err- | AH2: theta_int_err+ | AI2: vcirc_bestfit | AJ2: vcirc_peak | AK2: vcirc_median | AL2: vcirc_err- | AM2: vcirc_err+ | AN2: cosi_bestfit | AO2: cosi_peak | AP2: cosi_median | AQ2: cosi_err- | AR2: cosi_err+ | AS2: r_hl_disk_bestfit | AT2: r_hl_disk_peak | AU2: r_hl_disk_median | AV2: r_hl_disk_err- | AW2: r_hl_disk_err+ | AX2: flux_bestfit | AY2: flux_peak | AZ2: flux_median | BA2: flux_err- | BB2: flux_err+ | BC2: dx_disk_bestfit | BD2: dx_disk_peak | BE2: dx_disk_median | BF2: dx_disk_err- | BG2: dx_disk_err+ | BH2: dy_disk_bestfit | BI2: dy_disk_peak | BJ2: dy_disk_median | BK2: dy_disk_err- | BL2: dy_disk_err+ | BM2: vscale_bestfit | BN2: vscale_peak | BO2: vscale_median | BP2: vscale_err- | BQ2: vscale_err+
A3: 1 | B3: =IFERROR(AVERAGE(F3,L3,I3),"") | D3: F | E3: F (ns) | H3: F (ns) | K3: F (ns) | P3: 42.166334 | Q3: -3.4023557
A4: 2 | B4: =IFERROR(AVERAGE(F4,L4,I4),"") | D4: E | E4: E (fc) | H4: E (fc) | K4: E (fc) | P4: 42.195348 | Q4: -3.4206981
A5: 3 | B5: =IFERROR(AVERAGE(F5,L5,I5),"") | C5: 3 | D5: A | E5: F (ns) | H5: A | I5: 0.773 | J5: Hb,O3a,O3b | K5: B (sky) | L5: 0.773 | M5: O3a,O3b | O5: Hb,O3a | P5: 42.179617 | Q5: -3.4185339 | R5: 9.672 | S5: 0.098
A6: 4 | B6: =IFERROR(AVERAGE(F6,L6,I6),"") | C6: 3 | D6: B | E6: F (ns) | H6: B (sky) | I6: 0.668 | J6: Hb,O3b | K6: B (sky) | L6: 0.6685 | M6: Hb,O3b | P6: 42.202186 | Q6: -3.431905
A7: 5 | B7: =IFERROR(AVERAGE(F7,L7,I7),"") | C7: 3 | D7: A | E7: B (sky) | F7: 0.8465 | G7: Hb,O3b | H7: A | I7: 0.846 | J7: Hg,Hb,O3b | K7: A | L7: 0.846 | M7: Hb,O3b | O7: Hg | P7: 42.199228 | Q7: -3.4354826 | R7: 9.951 | S7: 0.052
A8: 6 | B8: =IFERROR(AVERAGE(F8,L8,I8),"") | D8: D | E8: D (gc) | H8: D (gc) | K8: D (gc) | P8: 42.176061 | Q8: -3.4287201
A9: 7 | B9: =IFERROR(AVERAGE(F9,L9,I9),"") | C9: 3 | D9: A | E9: A | F9: 0.411 | G9: N2a,N2b,Ha | H9: A | I9: 0.411 | J9: N2a,N2b,Ha | K9: A | L9: 0.4105 | M9: N2a,N2b,Ha | P9: 42.182724 | Q9: -3.4347805 | R9: 10.212 | S9: 0.028
A10: 8 | B10: =IFERROR(AVERAGE(F10,L10,I10),"") | C10: 3 | D10: A | E10: A | F10: 0.4915 | G10: Hb,O3a,O3b | H10: A | I10: 0.492 | J10: Hb,O3a,O3b | K10: A | L10: 0.492 | M10: Hb,O3a,O3b | O10: O3a | P10: 42.21353 | Q10: -3.4520444 | R10: 9.986 | S10: 0.042
A11: 9 | B11: =IFERROR(AVERAGE(F11,L11,I11),"") | D11: E | E11: E (fc) | H11: E (fc) | K11: E (fc) | P11: 42.177915 | Q11: -3.4385782
A12: 10 | B12: =IFERROR(AVERAGE(F12,L12,I12),"") | C12: 3 | D12: A | E12: B (sky) | F12: 0.6685 | G12: Hb,O3a,O3b | H12: A | I12: 0.669 | J12: Hb,O3a,O3b | K12: A | L12: 0.67 | M12: Hb,O3a,O3b | O12: O3a | P12: 42.216148 | Q12: -3.461236 | R12: 9.515 | S12: 0.066
A13: 11 | B13: =IFERROR(AVERAGE(F13,L13,I13),"") | D13: E | E13: E (fc) | H13: E (fc) | K13: E (fc) | P13: 42.215616 | Q13: -3.4642511
A14: 12 | B14: =IFERROR(AVERAGE(F14,L14,I14),"") | C14: 3 | D14: BS | E14: F (ns) | H14: B (sky) | I14: 0.479 | J14: Hb,O3a,O3b | K14: F (ns) | O14: Hb,O3a,O3b | P14: 42.170616 | Q14: -3.4479308
A15: 13 | B15: =IFERROR(AVERAGE(F15,L15,I15),"") | C15: 3 | D15: BS | E15: E (fc) | H15: B (sky) | I15: 0.846 | J15: O3a,O3b | K15: D (gc) | N15: More than one target in this slit, other z=0.2955 (N II, H alpha, S II; 3) | O15: O3a | P15: 42.139709 | Q15: -3.4376063 | R15: 9.521 | S15: 0.073
A16: 14 | B16: =IFERROR(AVERAGE(F16,L16,I16),"") | C16: 3 | D16: B | E16: B (sky) | F16: 0.584 | G16: O3b | H16: B (sky) | I16: 0.583 | J16: Hb,O3a,O3b | K16: B (sky) | L16: 0.584 | M16: Hb,O3b | O16: O3a | P16: 42.17938 | Q16: -3.4590941 | R16: 9.323 | S16: 0.091
A17: 15 | B17: =IFERROR(AVERAGE(F17,L17,I17),"") | C17: 2 | D17: B | E17: B (sky) | F17: 1.401 | G17: O2 | H17: B (sky) | I17: 1.399 | J17: O2 | K17: B (sky) | L17: 1.4 | M17: O2 | N17: Very extended line, 8 Angstrom | P17: 42.177477 | Q17: -3.461241 | R17: 9.578 | S17: 0.12
A18: 16 | B18: =IFERROR(AVERAGE(F18,L18,I18),"") | C18: 3 | D18: B | E18: B (sky) | F18: 0.682 | G18: O3b | H18: B (sky) | I18: 0.682 | J18: Hb,O3b | K18: B (sky) | L18: 0.682 | M18: O3b | O18: Hb | P18: 42.139733 | Q18: -3.4466916 | R18: 9.586 | S18: 0.046
A19: 17 | B19: =IFERROR(AVERAGE(F19,L19,I19),"") | C19: 3 | D19: AS | E19: F (ns) | H19: F (ns) | K19: A | L19: 0.612 | M19: Hb,O3a,O3b | O19: O3a,Hb | P19: 42.172676 | Q19: -3.4662291 | R19: 9.566 | S19: 0.09
A20: 18 | B20: =IFERROR(AVERAGE(F20,L20,I20),"") | C20: 3 | D20: A | E20: F (ns) | H20: A | I20: 0.847 | J20: Hb,O3b | K20: A | L20: 0.847 | M20: O3b | P20: 42.128581 | Q20: -3.4493951 | R20: 10.016 | S20: 0.051
A21: 19 | B21: =IFERROR(AVERAGE(F21,L21,I21),"") | C21: 3 | D21: A | E21: A | F21: 0.633 | G21: O3b | H21: A | I21: 0.633 | J21: Hb,O3b | K21: E (fc) | O21: Hb | P21: 42.132376 | Q21: -3.4546561 | R21: 9.306 | S21: 0.063
A22: 20 | B22: =IFERROR(AVERAGE(F22,L22,I22),"") | C22: 3 | D22: A | E22: F (ns) | H22: A | I22: 0.474 | J22: Hb,O3b | K22: A | L22: 0.474 | M22: O3b | P22: 42.195257 | Q22: -3.4888567 | R22: 8.656 | S22: 0.056
A23: 21 | B23: =IFERROR(AVERAGE(F23,L23,I23),"") | C23: 3 | D23: A | E23: A | F23: 0.903 | G23: O2 | H23: A | I23: 0.902 | J23: O2,Hb | K23: A | L23: 0.902 | M23: O2 | P23: 42.194816 | Q23: -3.4955871 | R23: 9.383 | S23: 0.055
A24: 22 | B24: =IFERROR(AVERAGE(F24,L24,I24),"") | D24: F | E24: F (ns) | H24: F (ns) | K24: F (ns) | P24: 42.197776 | Q24: -3.5000877
A25: 23 | B25: =IFERROR(AVERAGE(F25,L25,I25),"") | C25: 3 | D25: A | E25: A | F25: 0.5655 | G25: O3b | H25: A | I25: 0.566 | J25: O3a,O3b | K25: A | L25: 0.565 | M25: O3b | P25: 42.130406 | Q25: -3.4720578 | R25: 9.591 | S25: 0.083
A26: 24 | B26: =IFERROR(AVERAGE(F26,L26,I26),"") | C26: 3 | D26: A | E26: A | F26: 0.849 | G26: O3b | H26: A | I26: 0.848 | J26: Hg,Hb,O3a,O3b | K26: A | L26: 0.848 | M26: Hb,O3a,O3b | O26: Hb,Hg | P26: 42.137042 | Q26: -3.4785358 | R26: 9.696 | S26: 0.082
A27: 25 | B27: =IFERROR(AVERAGE(F27,L27,I27),"") | C27: 3 | D27: A | E27: F (ns) | H27: A | I27: 0.633 | J27: Hb,O3b | K27: A | L27: 0.633 | M27: Hb,O3b | P27: 42.112585 | Q27: -3.4700597 | R27: 9.39 | S27: 0.062
A28: 26 | B28: =IFERROR(AVERAGE(F28,L28,I28),"") | C28: 3 | D28: A | E28: E (fc) | H28: A | I28: 0.675 | J28: Hb | K28: B (sky) | L28: 0.674 | M28: Hb,O3b | N28: Single line, not likely [O II] | O28: O3a | P28: 42.208147 | Q28: -3.5172006 | R28: 9.97 | S28: 0.05
A29: 27 | B29: =IFERROR(AVERAGE(F29,L29,I29),"") | C29: 3 | D29: AS | E29: E (fc) | H29: E (fc) | K29: A | L29: 0.63 | M29: Hb,O3b | P29: 42.118436 | Q29: -3.478245 | R29: 9.924 | S29: 0.022
A30: 28 | B30: =IFERROR(AVERAGE(F30,L30,I30),"") | C30: 3 | D30: B | E30: F (ns) | H30: B (sky) | I30: 0.57 | J30: O3a,O3b | K30: B (sky) | L30: 0.57 | M30: O3b | O30: O3a | P30: 42.198081 | Q30: -3.5185422 | R30: 9.049 | S30: 0.117
A31: 29 | B31: =IFERROR(AVERAGE(F31,L31,I31),"") | C31: 3 | D31: A | E31: A | F31: 0.565 | G31: O3b | H31: A | I31: 0.564 | J31: O3a,O3b | K31: B (sky) | L31: 0.5635 | M31: O3a,O3b | O31: O3a | P31: 42.140826 | Q31: -3.4967561 | R31: 9.977 | S31: 0.014
A32: 30 | B32: =IFERROR(AVERAGE(F32,L32,I32),"") | C32: 3 | D32: A | E32: A | F32: 0.628 | G32: O3b | H32: A | I32: 0.628 | J32: Hb,O3a,O3b | K32: A | L32: 0.628 | M32: Hb,O3a,O3b | O32: Hb | P32: 42.122515 | Q32: -3.4913543 | R32: 9.576 | S32: 0.111
A33: 31 | B33: =IFERROR(AVERAGE(F33,L33,I33),"") | D33: C | E33: C (cs) | H33: C (cs) | K33: C (cs) | P33: 42.093127 | Q33: -3.4805345
A34: 32 | B34: =IFERROR(AVERAGE(F34,L34,I34),"") | C34: 2 | D34: B | E34: F (ns) | H34: B (sky) | I34: 1.1 | J34: O2 | K34: B (sky) | L34: 1.0995 | M34: O2 | P34: 42.134115 | Q34: -3.5044585 | R34: 9.628 | S34: 0.167
A35: 33 | B35: =IFERROR(AVERAGE(F35,L35,I35),"") | C35: 3 | D35: B | E35: F (ns) | H35: B (sky) | I35: 0.684 | J35: Hb,O3b | K35: B (sky) | L35: 0.684 | M35: Hb,O3b | O35: O3b | P35: 42.16135 | Q35: -3.52079 | R35: 9.888 | S35: 0.061
A36: 34 | B36: =IFERROR(AVERAGE(F36,L36,I36),"") | C36: 3 | D36: A | E36: B (sky) | F36: 0.657 | G36: O3b | H36: A | I36: 0.657 | J36: Hb,O3a,O3b | K36: A | L36: 0.6565 | M36: Hb,O3a,O3b | P36: 42.107535 | Q36: -3.4995786
A37: 35 | B37: =IFERROR(AVERAGE(F37,L37,I37),"") | C37: 3 | D37: B | E37: A | F37: 0.655 | G37: Hb,O3b | H37: B (sky) | I37: 0.657 | J37: Hb,O3b | K37: B (sky) | L37: 0.6575 | M37: Hb | N37: More than one target in this slit, other z=0.991 ([O II]; 2.5) | O37: O3b | P37: 42.106013 | Q37: -3.5026083 | R37: 9.936 | S37: 0.005
A38: 36 | B38: =IFERROR(AVERAGE(F38,L38,I38),"") | C38: 3 | D38: AS | E38: E (fc) | H38: A | I38: 0.528 | J38: Hb,O3b | K38: E (fc) | P38: 42.143129 | Q38: -3.5236084 | R38: 9.564 | S38: 0.057
A39: 37 | B39: =IFERROR(AVERAGE(F39,L39,I39),"") | D39: E | E39: E (fc) | H39: E (fc) | K39: E (fc) | P39: 42.118264 | Q39: -3.5148115
A40: 38 | B40: =IFERROR(AVERAGE(F40,L40,I40),"") | D40: E | E40: E (fc) | H40: E (fc) | K40: E (fc) | P40: 42.116043 | Q40: -3.5170309
...

Sheet other_calculations
A1: conf | B1: amount | D1: spec_quality | E1: amount
A2: 1 | B2: =COUNTIF(redshift_table!C3:C144, "") | D2: A | E2: =COUNTIF(redshift_table!D3:D144, "A")
A3: 2 | B3: =COUNTIF(redshift_table!C:C, 2) | D3: AS | E3: =COUNTIF(redshift_table!D3:D144, "AS")
A4: 3 | B4: =COUNTIF(redshift_table!C:C, 3) | D4: B | E4: =COUNTIF(redshift_table!D3:D144, "B")
D5: BS | E5: =COUNTIF(redshift_table!D3:D144, "BS")
D6: C | E6: =COUNTIF(redshift_table!D3:D144, "C")
D7: D | E7: =COUNTIF(redshift_table!D3:D144, "D")
D8: E | E8: =COUNTIF(redshift_table!D3:D144, "E")
D9: F | E9: =COUNTIF(redshift_table!D3:D144, "F")
